ERROR_2025-03-29 15:27:27,257_Traceback (most recent call last):
  File "C:\Users\rhashhanok\PycharmProjects\Logistics\base_app\contract_models\krd\kzvs.py", line 17, in start
    res, error_valid = dict_func.get(kwargs['submenu_selected'])(**kwargs)
                       ~~~~~~~~~~~~~~~~~~~~~~~~~~~~~~~~~~~~~~~~~^^^^^^^^^^
TypeError: 'NoneType' object is not callable

File: base_app.contract_models.krd.kzvs
Func: start
Error: 'NoneType' object is not callable.
